Workbook
Name Slicer_listed_in: #N/A
Name Slicer_Platform: #N/A
Name Slicer_rating: #N/A
Name Slicer_type: #N/A

Sheet OTT_Data
A1: show_id | B1: type | C1: title | D1: director | E1: cast | F1: country | G1: date_added | H1: Date_Status | I1: release_year | J1: rating | K1: duration | L1: duration_movies | M1: duration_tv | N1: listed_in | O1: description | P1: Platform | Q1: Platform_Id | R1: Added_year | S1: Added_month | T1: content_age | U1: Duration_category | Z1: DATA QUALITY CHECK | AA1: Column1
A2: s4849P | B2: Movie | C2: Contract Lovers | D2: Francisco Marcano | E2: Franko Marcano, Arune Kital, Vincent Rivera | F2: Unknown | H2: Unknown | I2: 2021 | J2: 16+ | K2: 79 min | L2: 79 | M2: 0 | N2: Action | O2: After working undercover contracts on the Middle East and South America for a mercenary company he left the war life to start a new one in the city but instead he become a contract killer after his girlfriend dead | P2: Prime Video | Q2: 2 | R2: =IF(G2="","",YEAR(G2)) | S2: =IF(G2="","",TEXT(G2,"mmmm")) | T2: =IF(I2>=2020,"Recent",IF(I2>=2010,"Modern","Older")) -> Recent | U2: =IF(L2=0,"Not Applicable",IF(L2< 90,"Short",IF(L2<=120,"Medium","Long"))) -> Short | Z2: Total Records | AA2: =COUNTA(A2:A3001) -> 3000
A3: s516N | B3: TV Show | C3: Derry Girls | D3: Michael Lennox | E3: Saoirse-Monica Jackson, Nicola Coughlan, Louisa Harland, Jamie-Lee O'Donnell, Dylan Llewellyn, Tara Lynne O'Neill, Kathy Kiera Clarke, Tommy Tiernan, Ian McElhinney, Siobhan McSweeney | F3: United Kingdom | G3: 44383 | H3: Available | I3: 2019 | J3: TV-MA | K3: 2 Seasons | L3: 0 | M3: 2 | N3: British TV Shows | O3: Amidst the political conflict of Northern Ireland in the 1990s, five high school students square off with the universal challenges of being a teenager. | P3: Netflix | Q3: 1 | R3: =IF(G3="","",YEAR(G3)) -> 2021 | S3: =IF(G3="","",TEXT(G3,"mmmm")) -> July | T3: =IF(I3>=2020,"Recent",IF(I3>=2010,"Modern","Older")) -> Modern | U3: =IF(L3=0,"Not Applicable",IF(L3< 90,"Short",IF(L3<=120,"Medium","Long"))) -> Not Applicable | Z3: Missing Date Added | AA3: =COUNTBLANK(G2:G3001) -> 1554
A4: s1544P | B4: Movie | C4: My Name Was Bette: The Life and Death of an Alcoholic | D4: Sherri L. VandenAkker | E4: Bette VandenAkker, Sherri VandenAkker | F4: Unknown | H4: Unknown | I4: 2014 | J4: 16+ | K4: 60 min | L4: 60 | M4: 0 | N4: Documentaries | O4: A documentary about women's alcoholism chronicles the progression of the disease in Bette VandenAkker-a nurse, wife, and mother-who died in the fall of 2007. | P4: Prime Video | Q4: 2 | R4: =IF(G4="","",YEAR(G4)) | S4: =IF(G4="","",TEXT(G4,"mmmm")) | T4: =IF(I4>=2020,"Recent",IF(I4>=2010,"Modern","Older")) -> Modern | U4: =IF(L4=0,"Not Applicable",IF(L4< 90,"Short",IF(L4<=120,"Medium","Long"))) -> Short | Z4: Unknown Directors | AA4: =COUNTIF(D2:D3001,"Unknown") -> 674
A5: s295N | B5: Movie | C5: Takizawa Kabuki ZERO 2020 The Movie | D5: Hideaki Takizawa | E5: Hikaru Iwamoto, Tatsuya Fukazawa, Raul, Shota Watanabe, Koji Mukai, Ryohei Abe, Ren Meguro, Ryota Miyadate, Daisuke Sakuma, Arata Sato, Tatsuya Kageyama, Taiga Suzuki, Shunsuke Motoi, Taiga Tsubaki, Yuki Yokohara, Minato Matsui, Shosei Oda | F5: Unknown | G5: 44415 | H5: Available | I5: 2020 | J5: TV-PG | K5: 139 min | L5: 139 | M5: 0 | N5: International Movies | O5: Superstar Hideaki Takizawa reimagines his acclaimed kabuki production for the screen, featuring the dynamic talents of idol group Snow Man. | P5: Netflix | Q5: 1 | R5: =IF(G5="","",YEAR(G5)) -> 2021 | S5: =IF(G5="","",TEXT(G5,"mmmm")) -> August | T5: =IF(I5>=2020,"Recent",IF(I5>=2010,"Modern","Older")) -> Recent | U5: =IF(L5=0,"Not Applicable",IF(L5< 90,"Short",IF(L5<=120,"Medium","Long"))) -> Long | Z5: Unknown Ratings | AA5: =COUNTIF(J:J,"Not Rated") -> 114
A6: s7173P | B6: Movie | C6: Greener Mountains | D6: Lee Shallat Chemel | E6: Chris Heuisler, Kimberly McCullough, Brad Raider, Kevin Durand | F6: Unknown | H6: Unknown | I6: 2004 | J6: 13+ | K6: 89 min | L6: 89 | M6: 0 | N6: Comedy | O6: Greener Mountains is a family friendly, coming-of-age story about finding your place in the world. | P6: Prime Video | Q6: 2 | R6: =IF(G6="","",YEAR(G6)) | S6: =IF(G6="","",TEXT(G6,"mmmm")) | T6: =IF(I6>=2020,"Recent",IF(I6>=2010,"Modern","Older")) -> Older | U6: =IF(L6=0,"Not Applicable",IF(L6< 90,"Short",IF(L6<=120,"Medium","Long"))) -> Short | Z6: Movies | AA6: =COUNTIF(B2:B3001,"Movie") -> 2264
A7: s5366N | B7: TV Show | C7: Vexed | D7: Unknown | E7: Toby Stephens, Miranda Raison, Lucy Punch, Nick Dunning, Rory Kinnear, Ronny Jhutti, Roger Griffiths, Patrick Baladi | F7: United Kingdom | G7: 42948 | H7: Available | I7: 2012 | J7: TV-MA | K7: 2 Seasons | L7: 0 | M7: 2 | N7: British TV Shows | O7: Charming slacker DI Jack Armstrong and driven professional DI Kate Bishop try to solve crimes together without driving each other crazy. | P7: Netflix | Q7: 1 | R7: =IF(G7="","",YEAR(G7)) -> 2017 | S7: =IF(G7="","",TEXT(G7,"mmmm")) -> August | T7: =IF(I7>=2020,"Recent",IF(I7>=2010,"Modern","Older")) -> Modern | U7: =IF(L7=0,"Not Applicable",IF(L7< 90,"Short",IF(L7<=120,"Medium","Long"))) -> Not Applicable | Z7: TV Shows | AA7: =COUNTIF(B2:B3001,"TV Show") -> 736
A8: s4649N | B8: TV Show | C8: If I were an Animal | D8: Unknown | E8: Zachary Young, Fleur Delahunty | F8: Unknown | G8: 43354 | H8: Available | I8: 2018 | J8: TV-G | K8: 1 Season | L8: 0 | M8: 1 | N8: Docuseries | O8: Curious kids Emma and her big brother Tim observe different animals as they make their way through various life milestones, from birth to adulthood. | P8: Netflix | Q8: 1 | R8: =IF(G8="","",YEAR(G8)) -> 2018 | S8: =IF(G8="","",TEXT(G8,"mmmm")) -> September | T8: =IF(I8>=2020,"Recent",IF(I8>=2010,"Modern","Older")) -> Modern | U8: =IF(L8=0,"Not Applicable",IF(L8< 90,"Short",IF(L8<=120,"Medium","Long"))) -> Not Applicable
A9: s4636P | B9: Movie | C9: Learn to Read with Max the Glow Train! | D9: Not Available | E9: Unknown | F9: Unknown | H9: Unknown | I9: 2016 | J9: ALL | K9: 6 min | L9: 6 | M9: 0 | N9: Kids | O9: Max the Glow Train and his friends receive an unusual device called a Word Machine. After they read a word the machine makes a toy. Something happens and the machine goes out of control! | P9: Prime Video | Q9: 2 | R9: =IF(G9="","",YEAR(G9)) | S9: =IF(G9="","",TEXT(G9,"mmmm")) | T9: =IF(I9>=2020,"Recent",IF(I9>=2010,"Modern","Older")) -> Modern | U9: =IF(L9=0,"Not Applicable",IF(L9< 90,"Short",IF(L9<=120,"Medium","Long"))) -> Short
A10: s2288N | B10: Movie | C10: Queen | D10: Vikas Bahl | E10: Kangana Ranaut, Rajkummar Rao, Lisa Haydon, Mish Boyko, Jeffrey Chee Eng Ho, Marco Canadea, Sabeeka Imam, Yogendra Tikku | F10: India | G10: 44017 | H10: Available | I10: 2014 | J10: TV-MA | K10: 138 min | L10: 138 | M10: 0 | N10: Comedy | O10: Dumped by her fiancé, a sheltered young woman decides to go on her honeymoon to Europe alone, embarking on an exhilarating journey of self-discovery. | P10: Netflix | Q10: 1 | R10: =IF(G10="","",YEAR(G10)) -> 2020 | S10: =IF(G10="","",TEXT(G10,"mmmm")) -> July | T10: =IF(I10>=2020,"Recent",IF(I10>=2010,"Modern","Older")) -> Modern | U10: =IF(L10=0,"Not Applicable",IF(L10< 90,"Short",IF(L10<=120,"Medium","Long"))) -> Long
A11: s4974P | B11: Movie | C11: Hoop Soldiers | D11: Chris Rogers | E11: Tank Jones, Cassandra King | F11: Unknown | H11: Unknown | I11: 2001 | J11: R | K11: 99 min | L11: 99 | M11: 0 | N11: Action | O11: While investigating her brother's death, a lawyer uncovers an illegal basketball league where the games are often fatal. | P11: Prime Video | Q11: 2 | R11: =IF(G11="","",YEAR(G11)) | S11: =IF(G11="","",TEXT(G11,"mmmm")) | T11: =IF(I11>=2020,"Recent",IF(I11>=2010,"Modern","Older")) -> Older | U11: =IF(L11=0,"Not Applicable",IF(L11< 90,"Short",IF(L11<=120,"Medium","Long"))) -> Medium
A12: s1211P | B12: Movie | C12: Rampage | D12: Uwe Boll | E12: Brendan Fletcher, Shaun Sipos, Michael ParÃ© | F12: Unknown | H12: Unknown | I12: 2011 | J12: R | K12: 85 min | L12: 85 | M12: 0 | N12: Action | O12: The boredom of small town life is eating Bill Williamson alive. Feeling constrained and claustrophobic in the meaningless drudgery of everyday life and helpless against overwhelming global dissolution, Bill (Brendan Fletcher) begins a descent into madness. His shockingly violent plan will shake the very foundations of society by painting the streets red with blood. | P12: Prime Video | Q12: 2 | R12: =IF(G12="","",YEAR(G12)) | S12: =IF(G12="","",TEXT(G12,"mmmm")) | T12: =IF(I12>=2020,"Recent",IF(I12>=2010,"Modern","Older")) -> Modern | U12: =IF(L12=0,"Not Applicable",IF(L12< 90,"Short",IF(L12<=120,"Medium","Long"))) -> Short
A13: s845N | B13: Movie | C13: Nail Bomber: Manhunt | D13: Daniel Vernon | E13: Unknown | F13: Unknown | G13: 44342 | H13: Available | I13: 2021 | J13: TV-MA | K13: 73 min | L13: 73 | M13: 0 | N13: Documentaries | O13: This documentary examines the 1999 London bombings that targeted Black, Bangladeshi and gay communities, and the race to find the far-right perpetrator. | P13: Netflix | Q13: 1 | R13: =IF(G13="","",YEAR(G13)) -> 2021 | S13: =IF(G13="","",TEXT(G13,"mmmm")) -> May | T13: =IF(I13>=2020,"Recent",IF(I13>=2010,"Modern","Older")) -> Recent | U13: =IF(L13=0,"Not Applicable",IF(L13< 90,"Short",IF(L13<=120,"Medium","Long"))) -> Short
A14: s60N | B14: Movie | C14: Naruto Shippuden: The Movie | D14: Hajime Kamegaki | E14: Junko Takeuchi, Chie Nakamura, Yoichi Masukawa, Koichi Tochika, Ayumi Fujimura, Keisuke Oda, Daisuke Kishio, Fumiko Orikasa, Hidetoshi Nakamura, Tetsuya Kakihara, Kisho Taniyama, Miyuki Sawashiro, Katsuyuki Konishi, Masako Katsuki, Keiko Nemoto, Masashi Ebara, Kazuhiko Inoue, Showtaro Morikubo, Romi Park, Daisuke Ono, Seizo Kato | F14: Japan | G14: 44454 | H14: Available | I14: 2007 | J14: TV-PG | K14: 95 min | L14: 95 | M14: 0 | N14: Action & Adventure | O14: The adventures of adolescent ninja Naruto Uzumaki continue as he's tasked with protecting a priestess from a demon – but to do so, he must die. | P14: Netflix | Q14: 1 | R14: =IF(G14="","",YEAR(G14)) -> 2021 | S14: =IF(G14="","",TEXT(G14,"mmmm")) -> September | T14: =IF(I14>=2020,"Recent",IF(I14>=2010,"Modern","Older")) -> Older | U14: =IF(L14=0,"Not Applicable",IF(L14< 90,"Short",IF(L14<=120,"Medium","Long"))) -> Medium
A15: s1092P | B15: Movie | C15: Sawan Ko Aane Do | D15: Kanak Mishra | E15: Arun Govil, Zarina Wahab, Amrish Puri, Rita Bhaduri, Yunus Parvez, Leela Mishra | F15: Unknown | H15: Unknown | I15: 1979 | J15: ALL | K15: 153 min | L15: 153 | M15: 0 | N15: Drama | O15: Sawan Ko Aane Do is a 1979 Rajshri Productions Hindi movie produced by Tarachand Barjatya and directed by Kanak Mishra. It's a story about Birju, a poor villager who wants to marry the headman's daughter, her father gets furious and sends her to the city. Years later, Birju becomes a successful singer and returns to seek his approval. | P15: Prime Video | Q15: 2 | R15: =IF(G15="","",YEAR(G15)) | S15: =IF(G15="","",TEXT(G15,"mmmm")) | T15: =IF(I15>=2020,"Recent",IF(I15>=2010,"Modern","Older")) -> Older | U15: =IF(L15=0,"Not Applicable",IF(L15< 90,"Short",IF(L15<=120,"Medium","Long"))) -> Long
A16: s7472P | B16: TV Show | C16: Alien Extinction | D16: Unknown | E16: Geovanni Molina | F16: Unknown | H16: Unknown | I16: 2020 | J16: 16+ | K16: 1 Season | L16: 0 | M16: 1 | N16: Action | O16: Earth has encountered an Alien that his sole mission is to destroy all human life . Two galactic bounty have been sent from another planet to stop the extinction of man before its to late. | P16: Prime Video | Q16: 2 | R16: =IF(G16="","",YEAR(G16)) | S16: =IF(G16="","",TEXT(G16,"mmmm")) | T16: =IF(I16>=2020,"Recent",IF(I16>=2010,"Modern","Older")) -> Recent | U16: =IF(L16=0,"Not Applicable",IF(L16< 90,"Short",IF(L16<=120,"Medium","Long"))) -> Not Applicable
A17: s1000N | B17: Movie | C17: Stowaway | D17: Joe Penna | E17: Anna Kendrick, Toni Collette, Daniel Dae Kim, Shamier Anderson | F17: Germany, United States | G17: 44308 | H17: Available | I17: 2021 | J17: TV-MA | K17: 116 min | L17: 116 | M17: 0 | N17: Drama | O17: A three-person crew on a mission to Mars faces an impossible choice when an unplanned passenger jeopardizes the lives of everyone on board. | P17: Netflix | Q17: 1 | R17: =IF(G17="","",YEAR(G17)) -> 2021 | S17: =IF(G17="","",TEXT(G17,"mmmm")) -> April | T17: =IF(I17>=2020,"Recent",IF(I17>=2010,"Modern","Older")) -> Recent | U17: =IF(L17=0,"Not Applicable",IF(L17< 90,"Short",IF(L17<=120,"Medium","Long"))) -> Medium
A18: s3950N | B18: TV Show | C18: Tango | D18: Unknown | E18: Bassel Khayyat, Daniella Rahme, Bassam Moughneih, Dana Mardini, Youssef Haddad, Talal Jarday, Sameera Barody | F18: Lebanon | G18: 43558 | H18: Available | I18: 2018 | J18: TV-14 | K18: 1 Season | L18: 0 | M18: 1 | N18: International TV Shows | O18: Shocking secrets begin to unravel when the aftermath of a car crash leaves four best friends questioning the truth of their relationships. | P18: Netflix | Q18: 1 | R18: =IF(G18="","",YEAR(G18)) -> 2019 | S18: =IF(G18="","",TEXT(G18,"mmmm")) -> April | T18: =IF(I18>=2020,"Recent",IF(I18>=2010,"Modern","Older")) -> Modern | U18: =IF(L18=0,"Not Applicable",IF(L18< 90,"Short",IF(L18<=120,"Medium","Long"))) -> Not Applicable
A19: s7940N | B19: Movie | C19: Sarvopari Palakkaran | D19: Venugopan | E19: Anoop Menon, Alencier Ley Lopez, Balu Varghese, Aparna Balamurali, Anu Sithara, Gayathri Arun, Nandu, Chali Pala | F19: India | G19: 43282 | H19: Available | I19: 2017 | J19: TV-14 | K19: 133 min | L19: 133 | M19: 0 | N19: Drama | O19: In the course of a human trafficking investigation, a conservative cop crosses paths with an artist-activist in a clash of worldviews. | P19: Netflix | Q19: 1 | R19: =IF(G19="","",YEAR(G19)) -> 2018 | S19: =IF(G19="","",TEXT(G19,"mmmm")) -> July | T19: =IF(I19>=2020,"Recent",IF(I19>=2010,"Modern","Older")) -> Modern | U19: =IF(L19=0,"Not Applicable",IF(L19< 90,"Short",IF(L19<=120,"Medium","Long"))) -> Long
A20: s1029P | B20: TV Show | C20: Shepherd | D20: Unknown | E20: Lance E. Nichols, Kelvin Harrison Jr., Alicia Davis Johnson, Chelsea Bryan | F20: Unknown | H20: Unknown | I20: 2021 | J20: 13+ | K20: 1 Season | L20: 0 | M20: 1 | N20: Drama | O20: Veteran actor Lance Nichols (Into the Badlands, House of Cards) heads this New Orleans-based cast as Father Joseph, a Catholic priest with a violent past who wages war with a dangerous drug lord after an attack at his church on Christmas Eve. Kelvin Harrison Jr. (Luce, Waves) co-stars as Will, a former altar boy turned drug dealer who gets caught up in Father Joseph's pursuit for justice. | P20: Prime Video | Q20: 2 | R20: =IF(G20="","",YEAR(G20)) | S20: =IF(G20="","",TEXT(G20,"mmmm")) | T20: =IF(I20>=2020,"Recent",IF(I20>=2010,"Modern","Older")) -> Recent | U20: =IF(L20=0,"Not Applicable",IF(L20< 90,"Short",IF(L20<=120,"Medium","Long"))) -> Not Applicable
A21: s1170P | B21: Movie | C21: Rhythm In the Clouds | D21: John H. Auer | E21: Patricia Ellis, Warren Hull, William Newell, Richard Carle, Zeffie Tilbury, Charles Judels, Robert Paige, Joyce Compton | F21: Unknown | H21: Unknown | I21: 1937 | J21: PG | K21: 53 min | L21: 53 | M21: 0 | N21: Arts | O21: Struggling songwriter Judy Walker talks her way into the apartment of a famous composer, and finds that he's on vacation. Homeless and without any money, she decides to stay at his place until his return, making use of all his belongings, and spreading the word that she is the composer's collaborator. She writes a song, wtih the composer listed as the co-writer, which becomes a big radio hit. The famous composer returns, and screwball comedy ensues. | P21: Prime Video | Q21: 2 | R21: =IF(G21="","",YEAR(G21)) | S21: =IF(G21="","",TEXT(G21,"mmmm")) | T21: =IF(I21>=2020,"Recent",IF(I21>=2010,"Modern","Older")) -> Older | U21: =IF(L21=0,"Not Applicable",IF(L21< 90,"Short",IF(L21<=120,"Medium","Long"))) -> Short
A22: s2057N | B22: Movie | C22: Hotel for Dogs | D22: Thor Freudenthal | E22: Emma Roberts, Jake T. Austin, Kyla Pratt, Lisa Kudrow, Kevin Dillon, Don Cheadle, Johnny Simmons, Troy Gentile, Eric Edelstein, Robinne Lee, Ajay Naidu | F22: Germany, United States | G22: 44076 | H22: Available | I22: 2009 | J22: PG | K22: 101 min | L22: 101 | M22: 0 | N22: Kids & Family Movies | O22: Placed in a foster home that doesn't allow pets, 16-year-old Andi and her younger brother Bruce turn an abandoned hotel into a home for their dog. | P22: Netflix | Q22: 1 | R22: =IF(G22="","",YEAR(G22)) -> 2020 | S22: =IF(G22="","",TEXT(G22,"mmmm")) -> September | T22: =IF(I22>=2020,"Recent",IF(I22>=2010,"Modern","Older")) -> Older | U22: =IF(L22=0,"Not Applicable",IF(L22< 90,"Short",IF(L22<=120,"Medium","Long"))) -> Medium
A23: s5309N | B23: Movie | C23: Rocco | D23: Thierry Demaizière, Alban Teurlai | E23: Rocco Siffredi | F23: France | G23: 42979 | H23: Available | I23: 2016 | J23: TV-MA | K23: 103 min | L23: 103 | M23: 0 | N23: Documentaries | O23: Italian porn star Rocco Siffredi is showcased in this documentary that shadows the legendary performer during his final year in front of the camera. | P23: Netflix | Q23: 1 | R23: =IF(G23="","",YEAR(G23)) -> 2017 | S23: =IF(G23="","",TEXT(G23,"mmmm")) -> September | T23: =IF(I23>=2020,"Recent",IF(I23>=2010,"Modern","Older")) -> Modern | U23: =IF(L23=0,"Not Applicable",IF(L23< 90,"Short",IF(L23<=120,"Medium","Long"))) -> Medium
A24: s6063N | B24: Movie | C24: A Walk to Remember | D24: Adam Shankman | E24: Mandy Moore, Shane West, Peter Coyote, Daryl Hannah, Lauren German, Clayne Crawford, Al Thompson | F24: United States | G24: 44013 | H24: Available | I24: 2002 | J24: PG | K24: 102 min | L24: 102 | M24: 0 | N24: Drama | O24: When bad boy Landon is cast opposite campus bookworm Jamie in a high school play, romance blooms — until tragedy threatens to tear them apart. | P24: Netflix | Q24: 1 | R24: =IF(G24="","",YEAR(G24)) -> 2020 | S24: =IF(G24="","",TEXT(G24,"mmmm")) -> July | T24: =IF(I24>=2020,"Recent",IF(I24>=2010,"Modern","Older")) -> Older | U24: =IF(L24=0,"Not Applicable",IF(L24< 90,"Short",IF(L24<=120,"Medium","Long"))) -> Medium
A25: s3750P | B25: Movie | C25: The Amazing Mr. Blunden | D25: Lionel Jeffries | E25: Laurence Naismith, Lynne Frederick, Gary Miller | F25: Unknown | H25: Unknown | I25: 1963 | J25: 13+ | K25: 84 min | L25: 84 | M25: 0 | N25: Fantasy | O25: The mysterious solicitor, Mr. Blunden, visits the near-destitute Mrs. Allen and her young Kids in her squalid, tiny Camden Town flat, and makes her an offer she can't refuse. The family becomes the housekeepers to a derelict country mansion in the charge of the solicitors. | P25: Prime Video | Q25: 2 | R25: =IF(G25="","",YEAR(G25)) | S25: =IF(G25="","",TEXT(G25,"mmmm")) | T25: =IF(I25>=2020,"Recent",IF(I25>=2010,"Modern","Older")) -> Older | U25: =IF(L25=0,"Not Applicable",IF(L25< 90,"Short",IF(L25<=120,"Medium","Long"))) -> Short
A26: s3246N | B26: TV Show | C26: Singapore Social | D26: Unknown | E26: Nicole Ong, Mae Tan, Sukki Singapora, Vinny Sharp, Paul Foster, Tabitha Nauser | F26: Singapore, United States | G26: 43791 | H26: Available | I26: 2019 | J26: TV-MA | K26: 1 Season | L26: 0 | M26: 1 | N26: International TV Shows | O26: Peer into the lives of young Singaporeans as they defy expectations and traverse the tricky terrain of career, romance and family. | P26: Netflix | Q26: 1 | R26: =IF(G26="","",YEAR(G26)) -> 2019 | S26: =IF(G26="","",TEXT(G26,"mmmm")) -> November | T26: =IF(I26>=2020,"Recent",IF(I26>=2010,"Modern","Older")) -> Modern | U26: =IF(L26=0,"Not Applicable",IF(L26< 90,"Short",IF(L26<=120,"Medium","Long"))) -> Not Applicable
A27: s5863P | B27: TV Show | C27: Da Kink In My Hair | D27: Unknown | E27: Ordena Stephens, Trey Anthony, Ngozi Paul | F27: Unknown | H27: Unknown | I27: 2009 | J27: TV-14 | K27: 2 Seasons | L27: 0 | M27: 2 | N27: Comedy | O27: Novelette's personal life picks up where it left off in season one - complicated! She is romantically involved with Richard, but his ex-wife and family get in the way. Making matters worse, Dre's father, Cedric, re-enters her life. As Novelette tries to untangle the webs in her personal life, she still has a shop to run and a family to look over. | P27: Prime Video | Q27: 2 | R27: =IF(G27="","",YEAR(G27)) | S27: =IF(G27="","",TEXT(G27,"mmmm")) | T27: =IF(I27>=2020,"Recent",IF(I27>=2010,"Modern","Older")) -> Older | U27: =IF(L27=0,"Not Applicable",IF(L27< 90,"Short",IF(L27<=120,"Medium","Long"))) -> Not Applicable
A28: s9173P | B28: Movie | C28: Je Suis A Stand-Up: Eddie Izzard Abroad | D28: Paul Tickell | E28: Eddie Izzard | F28: Unknown | H28: Unknown | I28: 1996 | J28: 18+ | K28: 48 min | L28: 48 | M28: 0 | N28: Arts | O28: BBC2 documentary of Eddie Izzard's first foray into world touring. Beginning in her "hometown" of Eastbourne and and culminating in his month long show in the East village of New York, Izzard travels to Paris (her first, unsuccessful French language show,) Copenhagen, Reykjavik, and Stockholm. | P28: Prime Video | Q28: 2 | R28: =IF(G28="","",YEAR(G28)) | S28: =IF(G28="","",TEXT(G28,"mmmm")) | T28: =IF(I28>=2020,"Recent",IF(I28>=2010,"Modern","Older")) -> Older | U28: =IF(L28=0,"Not Applicable",IF(L28< 90,"Short",IF(L28<=120,"Medium","Long"))) -> Short
A29: s2642N | B29: TV Show | C29: DreamWorks Spooky Stories: Volume 2 | D29: Unknown | E29: Seth Rogen, Will Arnett, Hugh Laurie, Will Ferrell, David Cross, Sean Bishop, Kiefer Sutherland, Cody Cameron, Aron Warner | F29: Unknown | G29: 43945 | H29: Available | I29: 2011 | J29: TV-PG | K29: 1 Season | L29: 0 | M29: 1 | N29: Kids | O29: The Shrek characters parody the music video "Thriller"; B.O.B. and pals battle zombie carrots; and Megamind faces the effects of the Button of Doom. | P29: Netflix | Q29: 1 | R29: =IF(G29="","",YEAR(G29)) -> 2020 | S29: =IF(G29="","",TEXT(G29,"mmmm")) -> April | T29: =IF(I29>=2020,"Recent",IF(I29>=2010,"Modern","Older")) -> Modern | U29: =IF(L29=0,"Not Applicable",IF(L29< 90,"Short",IF(L29<=120,"Medium","Long"))) -> Not Applicable
A30: s5912N | B30: Movie | C30: Jen Kirkman: I'm Gonna Die Alone (And I Feel Fine) | D30: Lance Bangs | E30: Jen Kirkman | F30: United States | G30: 42146 | H30: Available | I30: 2015 | J30: TV-MA | K30: 78 min | L30: 78 | M30: 0 | N30: Stand-Up Comedy | O30: Jen Kirkman delivers some sharp, hilarious truths about divorce, kids, sex and turning 40 in this Netflix original comedy special. | P30: Netflix | Q30: 1 | R30: =IF(G30="","",YEAR(G30)) -> 2015 | S30: =IF(G30="","",TEXT(G30,"mmmm")) -> May | T30: =IF(I30>=2020,"Recent",IF(I30>=2010,"Modern","Older")) -> Modern | U30: =IF(L30=0,"Not Applicable",IF(L30< 90,"Short",IF(L30<=120,"Medium","Long"))) -> Short
A31: s6394N | B31: TV Show | C31: Burnistoun | D31: Unknown | E31: Iain Connell, Robert Florence, Kirsty Strain, Richard Rankin, Allan Miller, Louise Stewart | F31: United Kingdom | G31: 43739 | H31: Available | I31: 2012 | J31: TV-MA | K31: 2 Seasons | L31: 0 | M31: 2 | N31: British TV Shows | O31: This sketch series focuses on the eccentric characters in a small Scottish town, including bumbling cops, "DJ Jesus" and a disgruntled serial killer. | P31: Netflix | Q31: 1 | R31: =IF(G31="","",YEAR(G31)) -> 2019 | S31: =IF(G31="","",TEXT(G31,"mmmm")) -> October | T31: =IF(I31>=2020,"Recent",IF(I31>=2010,"Modern","Older")) -> Modern | U31: =IF(L31=0,"Not Applicable",IF(L31< 90,"Short",IF(L31<=120,"Medium","Long"))) -> Not Applicable
A32: s3839N | B32: TV Show | C32: The Mechanism | D32: Unknown | E32: Selton Mello, Caroline Abras, Enrique Diaz, Antonio Saboia, Lee Taylor, Otto Jr., Leonardo Medeiros, Osvaldo Mil, Jonathan Haagensen, Giulio Lopes, Susana Ribeiro | F32: Brazil | G32: 43595 | H32: Available | I32: 2019 | J32: TV-MA | K32: 2 Seasons | L32: 0 | M32: 2 | N32: Crime TV Shows | O32: A scandal erupts in Brazil during an investigation of alleged government corruption via oil and construction companies. Loosely inspired by true events. | P32: Netflix | Q32: 1 | R32: =IF(G32="","",YEAR(G32)) -> 2019 | S32: =IF(G32="","",TEXT(G32,"mmmm")) -> May | T32: =IF(I32>=2020,"Recent",IF(I32>=2010,"Modern","Older")) -> Modern | U32: =IF(L32=0,"Not Applicable",IF(L32< 90,"Short",IF(L32<=120,"Medium","Long"))) -> Not Applicable
A33: s9641P | B33: Movie | C33: Meet the Spartans (Uncut) | D33: Jason Friedberg, Aaron Setzer | E33: Sean Maguire, Carmen Electra, Ken Davitian, Kevin Sorbo, Diedrich Bader, Method Man, Jareb Dauplaise, Travis Van Winkle, Phil Morris, Jim Piddock, Nicole Parker, Ike Barinholtz, Crista Flanagan, Hunter Clary, Emily Wilson, Thomas McKenna, Tiffany Haddish, Willie Macc, Kenny Yates, John Di Domenico, Christopher Lett, Jenny Costa, Belinda Waymouth, Jesse Lewis IV, Zachary Dylan Smith, Ryan Fraley, Tiffany Claus, Nick Steele, Jim Nieb, Dean Cochran, Nate Haden, Tony Yalda, Chris Crocker | F33: United States | H33: Unknown | I33: 2008 | J33: 18+ | K33: 86 min | L33: 86 | M33: 0 | N33: Comedy | O33: From the creators of Scary Movie and Date Movie comes this tongue-in-cheek parody of the sword-and-sandal epics. The heroic Leonidas, armed with nothing by leather underwear and a cape, leads a ragtag group of 13 - count 'em, 13! ? Spartans to defend their homeland against the invading Persians (whose ranks include Ghost Rider, Rocky Balboa, the Transformers, and a hunchbacked Paris Hilton... no one is safe when the Spartans take on the biggest icons in pop culture). | P33: Prime Video | Q33: 2 | R33: =IF(G33="","",YEAR(G33)) | S33: =IF(G33="","",TEXT(G33,"mmmm")) | T33: =IF(I33>=2020,"Recent",IF(I33>=2010,"Modern","Older")) -> Older | U33: =IF(L33=0,"Not Applicable",IF(L33< 90,"Short",IF(L33<=120,"Medium","Long"))) -> Short
A34: s5487N | B34: Movie | C34: The Devil's Mistress | D34: Filip Renc | E34: Tatiana Pauhofová, Karl Markovics, Gedeon Burkhard, Simona Stasová, Martin Huba, Pavel Kríz, Zdenka Procházková, Anna Fialová, Lenka Vlasáková, Jirí Mádl | F34: Czech Republic, Slovakia | G34: 42870 | H34: Available | I34: 2016 | J34: TV-MA | K34: 110 min | L34: 110 | M34: 0 | N34: Drama | O34: Before the dawn of World War II, an ambitious actress pursues her dreams in Berlin. But her plans derail when she becomes Joseph Goebbels’ mistress. | P34: Netflix | Q34: 1 | R34: =IF(G34="","",YEAR(G34)) -> 2017 | S34: =IF(G34="","",TEXT(G34,"mmmm")) -> May | T34: =IF(I34>=2020,"Recent",IF(I34>=2010,"Modern","Older")) -> Modern | U34: =IF(L34=0,"Not Applicable",IF(L34< 90,"Short",IF(L34<=120,"Medium","Long"))) -> Medium
A35: s1013P | B35: TV Show | C35: Sigmund and the Sea Monsters | D35: Unknown | E35: Rebecca Bloom, David Arquette, Solomon Stewart, Mark Povinelli, Eileen Oâ€™Connell, Drew Massey, Michael Oosterom, Victor Yerrid, Meegan Godfrey, David Crespin, Kyle Harrison Breitkopf | F35: Unknown | H35: Unknown | I35: 2017 | J35: 7+ | K35: 1 Season | L35: 0 | M35: 1 | N35: Kids | O35: Brothers Johnny and Scotty find Sigmund, a sea monster, on the beach and bring him home to their clubhouse. They become fast friends, but when a monster hunter, Capt. Barnabas (David Arquette), finds out, the kids have to scramble to keep Sigmund hidden. Worse still, Sigmund's brothers Blurp and Slurp don't like humans. Against all odds, can they still have an endless summer of fun? | P35: Prime Video | Q35: 2 | R35: =IF(G35="","",YEAR(G35)) | S35: =IF(G35="","",TEXT(G35,"mmmm")) | T35: =IF(I35>=2020,"Recent",IF(I35>=2010,"Modern","Older")) -> Modern | U35: =IF(L35=0,"Not Applicable",IF(L35< 90,"Short",IF(L35<=120,"Medium","Long"))) -> Not Applicable
A36: s4485N | B36: Movie | C36: Scorpion King 5: Book of Souls | D36: Don Michael Paul | E36: Zach McGowan, Pearl Thusi, Nathan Jones, Peter Mensah, Katy Louise Saunders, Mayling Ng, Howard Charles, Inge Beckmann | F36: United States | G36: 43396 | H36: Available | I36: 2018 | J36: PG-13 | K36: 102 min | L36: 102 | M36: 0 | N36: Action & Adventure | O36: The Scorpion King joins forces with a Nubian princess in an all-or-nothing fight to stop a warlord from claiming the souls of the vanquished. | P36: Netflix | Q36: 1 | R36: =IF(G36="","",YEAR(G36)) -> 2018 | S36: =IF(G36="","",TEXT(G36,"mmmm")) -> October | T36: =IF(I36>=2020,"Recent",IF(I36>=2010,"Modern","Older")) -> Modern | U36: =IF(L36=0,"Not Applicable",IF(L36< 90,"Short",IF(L36<=120,"Medium","Long"))) -> Medium
A37: s7735N | B37: Movie | C37: Phantom Boy | D37: Jean-Loup Felicioli, Alain Gagnol | E37: Marcus D'Angelo, Vincent D'Onofrio, Fred Armisen, Jared Padalecki, Joey Camen, Brian T. Delaney, Melissa Disney, Bill Lobley, Amanda Céline Miller, Dana Snyder, Stephanie Sheh | F37: France, Belgium | G37: 43009 | H37: Available | I37: 2015 | J37: PG | K37: 85 min | L37: 85 | M37: 0 | N37: Action & Adventure | O37: A boy whose illness allows him to float outside his body uses his newfound skill to help a cop take on a madman who's terrorizing New York City. | P37: Netflix | Q37: 1 | R37: =IF(G37="","",YEAR(G37)) -> 2017 | S37: =IF(G37="","",TEXT(G37,"mmmm")) -> October | T37: =IF(I37>=2020,"Recent",IF(I37>=2010,"Modern","Older")) -> Modern | U37: =IF(L37=0,"Not Applicable",IF(L37< 90,"Short",IF(L37<=120,"Medium","Long"))) -> Short
A38: s8559P | B38: Movie | C38: Chicago Massacre | D38: Michael Feifer | E38: Corin Nemec, Amy Lyndon | F38: Unknown | H38: Unknown | I38: 2007 | J38: R | K38: 92 min | L38: 92 | M38: 0 | N38: Documentaries | O38: A film based on the notorious mass killer Richard Speck, who systematically tortured, raped and murdered a group of student nurses from South Chicago Community Hospital in 1966. | P38: Prime Video | Q38: 2 | R38: =IF(G38="","",YEAR(G38)) | S38: =IF(G38="","",TEXT(G38,"mmmm")) | T38: =IF(I38>=2020,"Recent",IF(I38>=2010,"Modern","Older")) -> Older | U38: =IF(L38=0,"Not Applicable",IF(L38< 90,"Short",IF(L38<=120,"Medium","Long"))) -> Medium
A39: s2934N | B39: Movie | C39: Polaroid | D39: Lars Klevberg | E39: Kathryn Prescott, Mitch Pileggi, Grace Zabriskie, Tyler Young, Samantha Logan, Javier Botet, Katie Stevens, Madelaine Petsch, Priscilla Quintana, Davi Santos, Keenan Tracey | F39: United States, Norway, Canada | G39: 43870 | H39: Available | I39: 2019 | J39: PG-13 | K39: 88 min | L39: 88 | M39: 0 | N39: Horror | O39: A teen's discovery of a vintage Polaroid camera develops into a darker tale when she finds that whoever takes their photo with it dies soon afterward. | P39: Netflix | Q39: 1 | R39: =IF(G39="","",YEAR(G39)) -> 2020 | S39: =IF(G39="","",TEXT(G39,"mmmm")) -> February | T39: =IF(I39>=2020,"Recent",IF(I39>=2010,"Modern","Older")) -> Modern | U39: =IF(L39=0,"Not Applicable",IF(L39< 90,"Short",IF(L39<=120,"Medium","Long"))) -> Short
A40: s1651N | B40: Movie | C40: Shawn Mendes: Live in Concert | D40: Paul Dugdale | E40: Shawn Mendes | F40: United Kingdom, United States | G40: 44160 | H40: Available | I40: 2020 | J40: TV-PG | K40: 87 min | L40: 87 | M40: 0 | N40: Music & Musicals | O40: In his hometown of Toronto, Shawn Mendes pours his heart out on stage with a live performance in a stadium packed with adoring fans. | P40: Netflix | Q40: 1 | R40: =IF(G40="","",YEAR(G40)) -> 2020 | S40: =IF(G40="","",TEXT(G40,"mmmm")) -> November | T40: =IF(I40>=2020,"Recent",IF(I40>=2010,"Modern","Older")) -> Recent | U40: =IF(L40=0,"Not Applicable",IF(L40< 90,"Short",IF(L40<=120,"Medium","Long"))) -> Short
...

Sheet Content_Overview
A1: OTT Content Overview
A2: Netflix vs Prime Video - Content Composition and key metrices
A4: PLATFORM OVERVIEW | F4: CONTENT MIX
A5: METRIC | B5: Netflix | C5: prime video | D5: Total | F5: Content Type | G5: Percentage
A6: Total Content | B6: =COUNTIF(OTT_Data!P:P,"Netflix") -> 1431 | C6: =COUNTIF(OTT_Data!P:P,"Prime Video") -> 1569 | D6: =SUM(B6,C6) -> 3000 | F6: Movies | G6: =D7/Table2[[#This Row],[Total]] -> 0.75466667
A7: Movies | B7: =COUNTIFS(OTT_Data!P:P,"Netflix",OTT_Data!B:B,"Movie") -> 996 | C7: =COUNTIFS(OTT_Data!P:P,"Prime Video",OTT_Data!B:B,"Movie") -> 1268 | D7: =SUM(B7,C7) -> 2264 | F7: TV Shows | G7: =D8/D6 -> 0.24533333
A8: TV Shows | B8: =COUNTIFS(OTT_Data!P:P,"Netflix",OTT_Data!B:B,"TV Show") -> 435 | C8: =COUNTIFS(OTT_Data!P:P,"Prime Video",OTT_Data!B:B,"TV Show") -> 301 | D8: =SUM(B8:C8) -> 736
A10: RATING ANALYSIS
A11: Rating | B11: Netflix | C11: Prime Video | D11: Total | F11: PLATFORM CONTENT COMPOSITION
A12: 16+ | B12: =COUNTIFS(OTT_Data!$P:$P,"Netflix",OTT_Data!$J:$J,A12) -> 0 | C12: =COUNTIFS(OTT_Data!$P:$P,"Prime Video",OTT_Data!$J:$J,A12) -> 258 | D12: =SUM(B12:C12) -> 258 | F12: Content Type | G12: Netflix % | H12: Prime Video%
A13: 18+ | B13: =COUNTIFS(OTT_Data!$P:$P,"Netflix",OTT_Data!$J:$J,A13) -> 0 | C13: =COUNTIFS(OTT_Data!$P:$P,"Prime Video",OTT_Data!$J:$J,A13) -> 216 | D13: =SUM(B13:C13) -> 216 | F13: Movies | G13: =B7/B6 -> 0.69601677 | H13: =C7/C6 -> 0.80815806
A14: 13+ | B14: =COUNTIFS(OTT_Data!$P:$P,"Netflix",OTT_Data!$J:$J,A14) -> 0 | C14: =COUNTIFS(OTT_Data!$P:$P,"Prime Video",OTT_Data!$J:$J,A14) -> 350 | D14: =SUM(B14:C14) -> 350 | F14: TV Shows | G14: =B8/B6 -> 0.30398323 | H14: =C8/C6 -> 0.19184194
A15: TV-14 | B15: =COUNTIFS(OTT_Data!$P:$P,"Netflix",OTT_Data!$J:$J,A15) -> 351 | C15: =COUNTIFS(OTT_Data!$P:$P,"Prime Video",OTT_Data!$J:$J,A15) -> 42 | D15: =SUM(B15:C15) -> 393 | F15: Total | G15: =SUM(G13:G14) -> 1 | H15: =SUM(H13:H14) -> 1
A16: TV-MA | B16: =COUNTIFS(OTT_Data!$P:$P,"Netflix",OTT_Data!$J:$J,A16) -> 518 | C16: =COUNTIFS(OTT_Data!$P:$P,"Prime Video",OTT_Data!$J:$J,A16) -> 8 | D16: =SUM(B16:C16) -> 526
A17: PG-13 | B17: =COUNTIFS(OTT_Data!$P:$P,"Netflix",OTT_Data!$J:$J,A17) -> 101 | C17: =COUNTIFS(OTT_Data!$P:$P,"Prime Video",OTT_Data!$J:$J,A17) -> 56 | D17: =SUM(B17:C17) -> 157
A18: PG | B18: =COUNTIFS(OTT_Data!$P:$P,"Netflix",OTT_Data!$J:$J,A18) -> 51 | C18: =COUNTIFS(OTT_Data!$P:$P,"Prime Video",OTT_Data!$J:$J,A18) -> 33 | D18: =SUM(B18:C18) -> 84 | F18: KEY PLATFORM METRICS
A19: TV-PG | B19: =COUNTIFS(OTT_Data!$P:$P,"Netflix",OTT_Data!$J:$J,A19) -> 136 | C19: =COUNTIFS(OTT_Data!$P:$P,"Prime Video",OTT_Data!$J:$J,A19) -> 33 | D19: =SUM(B19:C19) -> 169 | F19: Total Titles | G19: 3000
A20: TV-G | B20: =COUNTIFS(OTT_Data!$P:$P,"Netflix",OTT_Data!$J:$J,A20) -> 36 | C20: =COUNTIFS(OTT_Data!$P:$P,"Prime Video",OTT_Data!$J:$J,A20) -> 13 | D20: =SUM(B20:C20) -> 49 | F20: Netflix Titles | G20: =B6 -> 1431
A21: G | B21: =COUNTIFS(OTT_Data!$P:$P,"Netflix",OTT_Data!$J:$J,A21) -> 2 | C21: =COUNTIFS(OTT_Data!$P:$P,"Prime Video",OTT_Data!$J:$J,A21) -> 19 | D21: =SUM(B21:C21) -> 21 | F21: Prime Video Titles | G21: =C6 -> 1569
A22: Not Rated | B22: =COUNTIFS(OTT_Data!$P:$P,"Netflix",OTT_Data!$J:$J,A22) -> 18 | C22: =COUNTIFS(OTT_Data!$P:$P,"Prime Video",OTT_Data!$J:$J,A22) -> 96 | D22: =SUM(B22:C22) -> 114 | F22: Total Movies | G22: =D7 -> 2264
F23: Total TV Shows | G23: =D8 -> 736
F24: Average Movie Duration | G24: =D27 -> 95.04115
A25: AVERAGE DURATION ANALYSIS
A26: Metric | B26: Netflix | C26: Prime Video | D26: Overall
A27: Average Movie Duration | B27: =AVERAGEIFS(OTT_Data!$L:$L,OTT_Data!$P:$P,"Netflix",OTT_Data!$L:$L,">0") -> 100.94975 | C27: =AVERAGEIFS(OTT_Data!$L:$L,OTT_Data!$P:$P,"Prime Video",OTT_Data!$L:$L,">0") -> 90.393676 | D27: =AVERAGEIF(OTT_Data!$L:$L,">0",OTT_Data!$L:$L) -> 95.04115 | F27: Netflix vs Prime Video — Content Type | K27: Average Movie Duration
A28: Short Movies | B28: =COUNTIFS(OTT_Data!$P:$P,"Netflix",OTT_Data!$U:$U,"Short") -> 274 | C28: =COUNTIFS(OTT_Data!$P:$P,"Prime Video",OTT_Data!$U:$U,"Short") -> 583 | D28: =SUM(B28:C28) -> 857
A29: Medium Movies | B29: =COUNTIFS(OTT_Data!$P:$P,"Netflix",OTT_Data!$U:$U,"Medium") -> 508 | C29: =COUNTIFS(OTT_Data!$P:$P,"Prime Video",OTT_Data!$U:$U,"Medium") -> 517 | D29: =SUM(B29:C29) -> 1025
A30: Long Movies | B30: =COUNTIFS(OTT_Data!$P:$P,"Netflix",OTT_Data!$U:$U,"Long") -> 213 | C30: =COUNTIFS(OTT_Data!$P:$P,"Prime Video",OTT_Data!$U:$U,"Long") -> 165 | D30: =SUM(B30:C30) -> 378
G46: Rating Distribution by Platform

Sheet Content_Trends
A1: OTT CONTENT TRENDS
A2: Year-wise analysis of content added across Netflix and Prime Video
A4: CONTENT ADDED BY YEAR | F4: Netflix Content Added by Year
A6: Year | B6: Netflix | C6: Total
A7: 2011 | B7: =COUNTIFS(OTT_Data!$R:$R,$A5,OTT_Data!$P:$P,"Netflix") -> 0 | C7: =SUM(B7:B7) -> 0
A8: 2013 | B8: =COUNTIFS(OTT_Data!$R:$R,$A6,OTT_Data!$P:$P,"Netflix") -> 0 | C8: =SUM(B8:B8) -> 0
A9: 2014 | B9: =COUNTIFS(OTT_Data!$R:$R,$A7,OTT_Data!$P:$P,"Netflix") -> 2 | C9: =SUM(B9:B9) -> 2
A10: 2015 | B10: =COUNTIFS(OTT_Data!$R:$R,$A8,OTT_Data!$P:$P,"Netflix") -> 3 | C10: =SUM(B10:B10) -> 3
A11: 2016 | B11: =COUNTIFS(OTT_Data!$R:$R,$A9,OTT_Data!$P:$P,"Netflix") -> 8 | C11: =SUM(B11:B11) -> 8
A12: 2017 | B12: =COUNTIFS(OTT_Data!$R:$R,$A10,OTT_Data!$P:$P,"Netflix") -> 11 | C12: =SUM(B12:B12) -> 11
A13: 2018 | B13: =COUNTIFS(OTT_Data!$R:$R,$A11,OTT_Data!$P:$P,"Netflix") -> 78 | C13: =SUM(B13:B13) -> 78
A14: 2019 | B14: =COUNTIFS(OTT_Data!$R:$R,$A12,OTT_Data!$P:$P,"Netflix") -> 171 | C14: =SUM(B14:B14) -> 171
A15: 2020 | B15: =COUNTIFS(OTT_Data!$R:$R,$A13,OTT_Data!$P:$P,"Netflix") -> 255 | C15: =SUM(B15:B15) -> 255
A16: 2021 | B16: =COUNTIFS(OTT_Data!$R:$R,$A14,OTT_Data!$P:$P,"Netflix") -> 334 | C16: =SUM(B16:B16) -> 334
A17: 2024 | B17: =COUNTIFS(OTT_Data!$R:$R,$A15,OTT_Data!$P:$P,"Netflix") -> 309 | C17: =SUM(B17:B17) -> 309
A19: DATE AVAILABILITY
A21: Metric | B21: Counts
A22: Total Netflix Titles | B22: =COUNTIF(OTT_Data!P:P,"Netflix") -> 1431 | F22: Availability of Added Year Data
A23: Netflix with Added Year | B23: =COUNTIFS(OTT_Data!P:P,"Netflix",OTT_Data!R:R,">0") -> 1429
A24: Netflix without Added Year | B24: =B22-B23 -> 2
A25: Total Prime Video Titles | B25: =COUNTIF(OTT_Data!P:P,"Prime Video") -> 1569
A26: Prime Video with Added Year | B26: =COUNTIFS(OTT_Data!P:P,"Prime Video",OTT_Data!R:R,">0") -> 17
A27: Prime Video without Added Year | B27: =B25-B26 -> 1552

Sheet content_country_genre_analysis
A1: OTT CONTENT ANALYSIS
A2: Movie, TV Show, Duration and Content Age Analysis
A4: CONTENT TYPE ANALYSIS | F4: Movies vs TV Shows by Platform | O4: Movie Duration Category Comparison | X4: Content Age Distribution by Platform
A5: Content Type | B5: Netflix | C5: Prime Video | D5: Total
A6: Movies | B6: =COUNTIFS(OTT_Data!$P:$P,"Netflix",OTT_Data!$B:$B,"Movie") -> 996 | C6: =COUNTIFS(OTT_Data!$P:$P,"Prime Video",OTT_Data!$B:$B,"Movie") -> 1268 | D6: =SUM(B6:C6) -> 2264
A7: TV Shows | B7: =COUNTIFS(OTT_Data!$P:$P,"Netflix",OTT_Data!$B:$B,"TV Show") -> 435 | C7: =COUNTIFS(OTT_Data!$P:$P,"Prime Video",OTT_Data!$B:$B,"TV Show") -> 301 | D7: =SUM(B7:C7) -> 736
A10: MOVIE DURATION ANALYSIS
A11: Metric | B11: Netflix | C11: Prime Video | D11: Overall
A12: Average Movie Duration | B12: =AVERAGEIFS(OTT_Data!$L:$L,OTT_Data!$P:$P,"Netflix",OTT_Data!$B:$B,"Movie") -> 100.84839 | C12: =AVERAGEIFS(OTT_Data!$L:$L,OTT_Data!$P:$P,"Prime Video",OTT_Data!$B:$B,"Movie") -> 90.179811 | D12: =AVERAGEIFS(OTT_Data!$L:$L,OTT_Data!$B:$B,"Movie") -> 94.873233
A13: Short Movies | B13: =COUNTIFS(OTT_Data!$P:$P,"Netflix",OTT_Data!$U:$U,"Short") -> 274 | C13: =COUNTIFS(OTT_Data!$P:$P,"Prime Video",OTT_Data!$U:$U,"Short") -> 583 | D13: =SUM(B13:C13) -> 857
A14: Medium Movies | B14: =COUNTIFS(OTT_Data!$P:$P,"Netflix",OTT_Data!$U:$U,"Medium") -> 508 | C14: =COUNTIFS(OTT_Data!$P:$P,"Prime Video",OTT_Data!$U:$U,"Medium") -> 517 | D14: =SUM(B14:C14) -> 1025
A15: Long Movies | B15: =COUNTIFS(OTT_Data!$P:$P,"Netflix",OTT_Data!$U:$U,"Long") -> 213 | C15: =COUNTIFS(OTT_Data!$P:$P,"Prime Video",OTT_Data!$U:$U,"Long") -> 165 | D15: =SUM(B15:C15) -> 378
A17: CONTENT AGE ANALYSIS
A18: Metric | B18: Netflix | C18: Prime Video | D18: Overall
A19: Recent | B19: =COUNTIFS(OTT_Data!$P:$P,"Netflix",OTT_Data!$T:$T,"Recent") -> 264 | C19: =COUNTIFS(OTT_Data!$P:$P,"Prime Video",OTT_Data!$T:$T,"Recent") -> 407 | D19: =SUM(B19:C19) -> 671
A20: Modern | B20: =COUNTIFS(OTT_Data!$P:$P,"Netflix",OTT_Data!$T:$T,"Modern") -> 937 | C20: =COUNTIFS(OTT_Data!$P:$P,"Prime Video",OTT_Data!$T:$T,"Modern") -> 692 | D20: =SUM(B20:C20) -> 1629
A21: Older | B21: =COUNTIFS(OTT_Data!$P:$P,"Netflix",OTT_Data!$T:$T,"Older") -> 230 | C21: =COUNTIFS(OTT_Data!$P:$P,"Prime Video",OTT_Data!$T:$T,"Older") -> 470 | D21: =SUM(B21:C21) -> 700
A24: OTT COUNTRY ANALYSIS
A25: COUNTRY-WISE CONTENT DISTRIBUTION ACROSS NETFLIX AND PRIME VIDEO | K25: Country-wise OTT Content Distribution | S25: Netflix vs Prime Video — Country Comparison
A27: Country | B27: Total Titles
A28: United States | B28: =COUNTIF(OTT_Data!$F:$F,"*"&A28&"*") -> 748
A29: India | B29: =COUNTIF(OTT_Data!$F:$F,"*"&A29&"*") -> 216
A30: United Kingdom | B30: =COUNTIF(OTT_Data!$F:$F,"*"&A30&"*") -> 167
A31: France | B31: =COUNTIF(OTT_Data!$F:$F,"*"&A31&"*") -> 79
A32: Canada | B32: =COUNTIF(OTT_Data!$F:$F,"*"&A32&"*") -> 67
A33: Japan | B33: =COUNTIF(OTT_Data!$F:$F,"*"&A33&"*") -> 60
A34: Germany | B34: =COUNTIF(OTT_Data!$F:$F,"*"&A34&"*") -> 50
A35: Spain | B35: =COUNTIF(OTT_Data!$F:$F,"*"&A35&"*") -> 44
A36: Australia | B36: =COUNTIF(OTT_Data!$F:$F,"*"&A36&"*") -> 35
A37: Mexico | B37: =COUNTIF(OTT_Data!$F:$F,"*"&A37&"*") -> 26
A39: NETFLIX VS PRIME VIDEO — COUNTRY COMPARISON
A40: Country | B40: Netflix | C40: Prime Video
A41: United States | B41: =COUNTIFS(OTT_Data!$F:$F,"*"&A41&"*",OTT_Data!$P:$P,"Netflix") -> 629 | C41: =COUNTIFS(OTT_Data!$F:$F,"*"&A41&"*",OTT_Data!$P:$P,"Prime Video") -> 119
A42: India | B42: =COUNTIFS(OTT_Data!$F:$F,"*"&A42&"*",OTT_Data!$P:$P,"Netflix") -> 172 | C42: =COUNTIFS(OTT_Data!$F:$F,"*"&A42&"*",OTT_Data!$P:$P,"Prime Video") -> 44
A43: United Kingdom | B43: =COUNTIFS(OTT_Data!$F:$F,"*"&A43&"*",OTT_Data!$P:$P,"Netflix") -> 134 | C43: =COUNTIFS(OTT_Data!$F:$F,"*"&A43&"*",OTT_Data!$P:$P,"Prime Video") -> 33
A44: France | B44: =COUNTIFS(OTT_Data!$F:$F,"*"&A44&"*",OTT_Data!$P:$P,"Netflix") -> 74 | C44: =COUNTIFS(OTT_Data!$F:$F,"*"&A44&"*",OTT_Data!$P:$P,"Prime Video") -> 5
A45: Canada | B45: =COUNTIFS(OTT_Data!$F:$F,"*"&A45&"*",OTT_Data!$P:$P,"Netflix") -> 56 | C45: =COUNTIFS(OTT_Data!$F:$F,"*"&A45&"*",OTT_Data!$P:$P,"Prime Video") -> 11
A46: Japan | B46: =COUNTIFS(OTT_Data!$F:$F,"*"&A46&"*",OTT_Data!$P:$P,"Netflix") -> 53 | C46: =COUNTIFS(OTT_Data!$F:$F,"*"&A46&"*",OTT_Data!$P:$P,"Prime Video") -> 7
A47: Germany | B47: =COUNTIFS(OTT_Data!$F:$F,"*"&A47&"*",OTT_Data!$P:$P,"Netflix") -> 46 | C47: =COUNTIFS(OTT_Data!$F:$F,"*"&A47&"*",OTT_Data!$P:$P,"Prime Video") -> 4
A48: Spain | B48: =COUNTIFS(OTT_Data!$F:$F,"*"&A48&"*",OTT_Data!$P:$P,"Netflix") -> 39 | C48: =COUNTIFS(OTT_Data!$F:$F,"*"&A48&"*",OTT_Data!$P:$P,"Prime Video") -> 5
...

Sheet pivot_table_analysis
A1: OTT Pivot Table Analysis
A3: Pivot 1:Platform-wise Content | E3: Pivot 2:Platform vs Genre | I3: Pivot 3:Year-wise Content
A4: Row Labels | B4: Count of type | C4: Count of show_id | E4: Count of title | F4: Column Labels | I4: Row Labels | J4: Count of title
A5: Prime Video | B5: 17 | C5: 17 | E5: Row Labels | F5: Prime Video | G5: Grand Total | I5: 1947 | J5: 1
A6: Grand Total | B6: 17 | C6: 17 | E6: Action | F6: 8 | G6: 8 | I6: 1955 | J6: 1
E7: Drama | F7: 7 | G7: 7 | I7: 1964 | J7: 1
E8: Romance | F8: 1 | G8: 1 | I8: 1973 | J8: 1
A9: Pivot 4:Genre-wise Content | E9: Young Adult Audience | F9: 1 | G9: 1 | I9: 1995 | J9: 1
A10: Row Labels | B10: Count of title | E10: Grand Total | F10: 17 | G10: 17 | I10: 2003 | J10: 1
A11: Action | B11: 8 | I11: 2007 | J11: 1
A12: Drama | B12: 7 | I12: 2011 | J12: 1
A13: Romance | B13: 1 | I13: 2015 | J13: 1
A14: Young Adult Audience | B14: 1 | I14: 2016 | J14: 1
A15: Grand Total | B15: 17 | I15: 2018 | J15: 1
I16: 2019 | J16: 2
I17: 2021 | J17: 4
I18: Grand Total | J18: 17
E61: Pivot 5:Movies vs TV Shows
E62: Row Labels | F62: Count of title
E63: Movie | F63: 13
E64: TV Show | F64: 4
E65: Grand Total | F65: 17

Sheet ott_dashboard
A1: OTT CONTENT ANALYSIS DASHBOARD
A5: Platform Distribution | D5: Movies vs TV Shows | I5: Genre-wise OTT Content Distribution | M5: Netflix vs Prime Video by Genre

Sheet Summary
A1: KEY INSIGHTS / SUMMARY
A3: Insight | B3: Finding
A4: Total Content | B4: 3,000 titles are available across both OTT platforms.
A5: Platform Leader | B5: Prime Video has 1,569 titles, slightly more than Netflix's 1,431.
A6: Content Type | B6: Movies dominate with 2,264 titles, while TV Shows have 736.
A7: Top Genre | B7: Drama is the largest genre with 656 titles.
A8: Second Largest Genre | B8: Comedy has 470 titles.
A9: Action Content | B9: Action has 266 titles.
A10: Content Growth | B10: Content increases significantly from 2014 onward, with 2020–2021 having the highest yearly counts in your data.
A11: Platform Comparison | B11: Prime Video has more total titles than Netflix, but the distribution varies by genre.
